<?xml version="1.0"?>
<robot xmlns:xacro="http://www.ros.org/wiki/xacro" name="embodied_robot">
  <xacro:property name="pi" value="3.141592653589793"/>
  <xacro:property name="wheel_radius" value="0.09"/>
  <xacro:property name="wheel_width" value="0.045"/>
  <xacro:property name="wheel_y" value="0.22"/>
  <xacro:property name="wheel_x" value="0.18"/>

  <xacro:macro name="box_inertial" params="mass x y z">
    <inertial>
      <mass value="${mass}"/>
      <inertia ixx="${mass * (y*y + z*z) / 12.0}" ixy="0" ixz="0"
               iyy="${mass * (x*x + z*z) / 12.0}" iyz="0"
               izz="${mass * (x*x + y*y) / 12.0}"/>
    </inertial>
  </xacro:macro>

  <xacro:macro name="cylinder_inertial" params="mass radius length">
    <inertial>
      <mass value="${mass}"/>
      <inertia ixx="${mass * (3*radius*radius + length*length) / 12.0}" ixy="0" ixz="0"
               iyy="${mass * (3*radius*radius + length*length) / 12.0}" iyz="0"
               izz="${mass * radius*radius / 2.0}"/>
    </inertial>
  </xacro:macro>

  <xacro:macro name="wheel_inertial" params="mass radius length">
    <inertial>
      <origin rpy="${pi/2} 0 0"/>
      <mass value="${mass}"/>
      <inertia ixx="${mass * (3*radius*radius + length*length) / 12.0}" ixy="0" ixz="0"
               iyy="${mass * (3*radius*radius + length*length) / 12.0}" iyz="0"
               izz="${mass * radius*radius / 2.0}"/>
    </inertial>
  </xacro:macro>

  <material name="blue"><color rgba="0.1 0.35 0.8 1"/></material>
  <material name="dark"><color rgba="0.12 0.12 0.14 1"/></material>
  <material name="orange"><color rgba="1.0 0.45 0.05 1"/></material>
  <material name="silver"><color rgba="0.65 0.68 0.72 1"/></material>

  <link name="base_footprint"/>

  <joint name="base_footprint_joint" type="fixed">
    <parent link="base_footprint"/>
    <child link="base_link"/>
    <origin xyz="0 0 0.20"/>
  </joint>

  <link name="base_link">
    <visual>
      <geometry><box size="0.52 0.42 0.18"/></geometry>
      <material name="blue"/>
    </visual>
    <collision><geometry><box size="0.52 0.42 0.18"/></geometry></collision>
    <xacro:box_inertial mass="12.0" x="0.52" y="0.42" z="0.18"/>
  </link>

  <xacro:macro name="wheel" params="prefix x y">
    <link name="${prefix}_wheel_link">
      <visual>
        <origin rpy="${pi/2} 0 0"/>
        <geometry><cylinder radius="${wheel_radius}" length="${wheel_width}"/></geometry>
        <material name="dark"/>
      </visual>
      <collision>
        <origin rpy="${pi/2} 0 0"/>
        <geometry><cylinder radius="${wheel_radius}" length="${wheel_width}"/></geometry>
      </collision>
      <xacro:wheel_inertial mass="0.8" radius="${wheel_radius}" length="${wheel_width}"/>
    </link>
    <joint name="${prefix}_wheel_joint" type="continuous">
      <parent link="base_link"/>
      <child link="${prefix}_wheel_link"/>
      <origin xyz="${x} ${y} -0.105"/>
      <axis xyz="0 1 0"/>
      <dynamics damping="0.05" friction="0.0"/>
    </joint>
    <gazebo reference="${prefix}_wheel_link">
      <mu1>1.2</mu1><mu2>1.2</mu2><kp>1000000</kp><kd>10</kd>
    </gazebo>
  </xacro:macro>

  <!-- Keep the original joint names for the front wheels so existing checks remain valid. -->
  <xacro:wheel prefix="left" x="${wheel_x}" y="${wheel_y}"/>
  <xacro:wheel prefix="right" x="${wheel_x}" y="${-wheel_y}"/>
  <xacro:wheel prefix="left_rear" x="${-wheel_x}" y="${wheel_y}"/>
  <xacro:wheel prefix="right_rear" x="${-wheel_x}" y="${-wheel_y}"/>

  <link name="arm_base_link">
    <visual><geometry><cylinder radius="0.10" length="0.08"/></geometry><material name="silver"/></visual>
    <collision><geometry><cylinder radius="0.10" length="0.08"/></geometry></collision>
    <xacro:cylinder_inertial mass="1.0" radius="0.10" length="0.08"/>
  </link>
  <joint name="arm_base_joint" type="fixed">
    <parent link="base_link"/><child link="arm_base_link"/>
    <origin xyz="0 0 0.13"/>
  </joint>

  <link name="arm_link_1">
    <visual><origin xyz="0 0 0.18"/><geometry><box size="0.07 0.07 0.36"/></geometry><material name="orange"/></visual>
    <collision><origin xyz="0 0 0.18"/><geometry><box size="0.07 0.07 0.36"/></geometry></collision>
    <inertial>
      <origin xyz="0 0 0.18"/>
      <mass value="1.2"/>
      <inertia ixx="0.01345" ixy="0" ixz="0" iyy="0.01345" iyz="0" izz="0.00098"/>
    </inertial>
  </link>
  <joint name="arm_joint_1" type="revolute">
    <parent link="arm_base_link"/><child link="arm_link_1"/>
    <origin xyz="0 0 0.04"/><axis xyz="0 1 0"/>
    <limit lower="-1.20" upper="1.20" effort="35" velocity="1.5"/>
    <dynamics damping="0.8" friction="0.1"/>
  </joint>

  <link name="arm_link_2">
    <visual><origin xyz="0 0 0.15"/><geometry><box size="0.06 0.06 0.30"/></geometry><material name="orange"/></visual>
    <collision><origin xyz="0 0 0.15"/><geometry><box size="0.06 0.06 0.30"/></geometry></collision>
    <inertial>
      <origin xyz="0 0 0.15"/>
      <mass value="0.8"/>
      <inertia ixx="0.00624" ixy="0" ixz="0" iyy="0.00624" iyz="0" izz="0.00048"/>
    </inertial>
  </link>
  <joint name="arm_joint_2" type="revolute">
    <parent link="arm_link_1"/><child link="arm_link_2"/>
    <origin xyz="0 0 0.36"/><axis xyz="0 1 0"/>
    <limit lower="-1.50" upper="1.50" effort="25" velocity="1.8"/>
    <dynamics damping="0.6" friction="0.08"/>
  </joint>

  <link name="tool_link">
    <visual name="gripper_palm_visual">
      <origin xyz="0 0 0.025"/>
      <geometry><box size="0.10 0.16 0.05"/></geometry>
      <material name="silver"/>
    </visual>
    <visual name="left_finger_visual">
      <origin xyz="0 0.065 0.11"/>
      <geometry><box size="0.04 0.03 0.14"/></geometry>
      <material name="dark"/>
    </visual>
    <visual name="right_finger_visual">
      <origin xyz="0 -0.065 0.11"/>
      <geometry><box size="0.04 0.03 0.14"/></geometry>
      <material name="dark"/>
    </visual>
    <collision name="gripper_palm_collision">
      <origin xyz="0 0 0.025"/>
      <geometry><box size="0.10 0.16 0.05"/></geometry>
    </collision>
    <collision name="left_finger_collision">
      <origin xyz="0 0.065 0.11"/>
      <geometry><box size="0.04 0.03 0.14"/></geometry>
    </collision>
    <collision name="right_finger_collision">
      <origin xyz="0 -0.065 0.11"/>
      <geometry><box size="0.04 0.03 0.14"/></geometry>
    </collision>
    <inertial>
      <origin xyz="0 0 0.07"/>
      <mass value="0.35"/>
      <inertia ixx="0.00120" ixy="0" ixz="0" iyy="0.00065" iyz="0" izz="0.00125"/>
    </inertial>
  </link>
  <joint name="tool_joint" type="fixed">
    <parent link="arm_link_2"/><child link="tool_link"/><origin xyz="0 0 0.30"/>
  </joint>

  <link name="camera_link">
    <visual><geometry><box size="0.08 0.10 0.07"/></geometry><material name="dark"/></visual>
    <collision><geometry><box size="0.08 0.10 0.07"/></geometry></collision>
    <xacro:box_inertial mass="0.2" x="0.08" y="0.10" z="0.07"/>
  </link>
  <joint name="camera_joint" type="fixed">
    <parent link="base_link"/><child link="camera_link"/>
    <origin xyz="0.27 0 0.10"/>
  </joint>

  <link name="camera_optical_link"/>
  <joint name="camera_optical_joint" type="fixed">
    <parent link="camera_link"/><child link="camera_optical_link"/>
    <origin xyz="0.045 0 0" rpy="${-pi/2} 0 ${-pi/2}"/>
  </joint>

  <transmission name="arm_joint_1_transmission">
    <type>transmission_interface/SimpleTransmission</type>
    <joint name="arm_joint_1"><hardwareInterface>hardware_interface/EffortJointInterface</hardwareInterface></joint>
    <actuator name="arm_joint_1_motor"><hardwareInterface>hardware_interface/EffortJointInterface</hardwareInterface><mechanicalReduction>1</mechanicalReduction></actuator>
  </transmission>
  <transmission name="arm_joint_2_transmission">
    <type>transmission_interface/SimpleTransmission</type>
    <joint name="arm_joint_2"><hardwareInterface>hardware_interface/EffortJointInterface</hardwareInterface></joint>
    <actuator name="arm_joint_2_motor"><hardwareInterface>hardware_interface/EffortJointInterface</hardwareInterface><mechanicalReduction>1</mechanicalReduction></actuator>
  </transmission>

  <gazebo>
    <plugin name="gazebo_ros_control" filename="libgazebo_ros_control.so">
      <robotNamespace>/</robotNamespace>
    </plugin>
  </gazebo>

  <gazebo>
    <plugin name="skid_steer_drive_controller" filename="libgazebo_ros_skid_steer_drive.so">
      <robotNamespace>/</robotNamespace>
      <leftFrontJoint>left_wheel_joint</leftFrontJoint>
      <rightFrontJoint>right_wheel_joint</rightFrontJoint>
      <leftRearJoint>left_rear_wheel_joint</leftRearJoint>
      <rightRearJoint>right_rear_wheel_joint</rightRearJoint>
      <wheelSeparation>${2 * wheel_y}</wheelSeparation>
      <wheelDiameter>${2 * wheel_radius}</wheelDiameter>
      <torque>15</torque>
      <commandTopic>cmd_vel</commandTopic>
      <odometryTopic>odom</odometryTopic>
      <odometryFrame>odom</odometryFrame>
      <robotBaseFrame>base_footprint</robotBaseFrame>
      <broadcastTF>true</broadcastTF>
      <updateRate>50</updateRate>
    </plugin>
  </gazebo>

  <gazebo reference="camera_link">
    <sensor type="camera" name="front_camera">
      <update_rate>20</update_rate>
      <camera name="front">
        <horizontal_fov>1.047</horizontal_fov>
        <image><width>640</width><height>480</height><format>R8G8B8</format></image>
        <clip><near>0.05</near><far>20</far></clip>
      </camera>
      <plugin name="camera_controller" filename="libgazebo_ros_camera.so">
        <robotNamespace>/</robotNamespace>
        <cameraName>camera</cameraName>
        <imageTopicName>image_raw</imageTopicName>
        <cameraInfoTopicName>camera_info</cameraInfoTopicName>
        <frameName>camera_optical_link</frameName>
      </plugin>
    </sensor>
  </gazebo>
</robot>
